Workbook

Sheet Försättsblad
A4: Dokument/Listor | B4: Beskrivning
A5: Beställningar - huvudfil | B5: Orderfilen med alla beställningar
A6: Lager "På vift" | B6: Dragkrokar mm. som finns "i lager" men inte i Borås - än.. Här ska alla krokar som är extra eller blir över föras in. När någon vara tas härifrån, ska den markeras röd samt skrivas i kolumn P till vilken bil den tas. När en vara legat röd ett tag, sätt ett "x" i kolumn O. Om dragkrokar tas hem till Borås, markera hela raden i gult och skriv i kolumn S.
A7: Lager Borås | B7: Administration lagret i Borås
A8: Prislista dragkrokar | B8: Prislista för dragkrokar. Westfalia, Witter, Steinhof och Imiola finns i huvudfliken. Övriga går att hitta i separat blad i filen.
A9: Prislista ECS | B9: Prislista på elsatser från ECS. Aktuellt lagersaldo hemma finns i kolumn J (Borås) och K ("På vift"-listan)
A10: Menabo Application list | B10: Aktuell lista från Menabo med vilka takräcken som passar vilka bilar.
A11: Order Steinhof | B11: Fil som vi lägger in alla ordrar till Steinhof. Ordrar som läggs innan kl 10.00 skickas samma dag.
A12: Order Imiola | B12: Fil som vi lägger in alla ordrar till Imiola. Lägg även ett mail till Imiola (office@imiola.pl) när order lagts här i, de går inte in och kikar regelbundet som Steinhof.
A13: Order Westfalia | B13: Ordrar till Westfalia läggs i deras Webshop. Det går även att beställa via mail till ea-dk-sales@horizonglobal.com eller telefon ‭0220-225 41‬
A14: Order Martec | B14: Ordrar på Autohak eller Brink görs per mail till Martec, export@martec.pl. Martec lägger sedan in ordrarna i denna fil.
A15: Order Umbra Rimorchi | B15: Ordrar på Umbra läggs i detta dokumentet. Skicka ett mail till export@umbrarimorchi.it när order lagts. De kikar inte jämnt i denna listan.
... A22: Bibeln | B22: Bibeln med frågor och svar samt lite policy som vi samlat på oss genom åren.
A25: Google Drive
A26: Delade dokument och bra att ha | B26: Finns i Google drive länkat
A28: Statistik
A29: Försäljning Statistik
A33: Dokument
A34: Marknadsföring: Leverantörer | B34: Texter och beskrivningar om våra leverantörer
A35: Produktblad Monteringspartner | B35: Produktblad monteringspartners, hur vi jobbar och fördelningar mm

Sheet Lager
M1: SKA TILL: | AB1: 1€= | AC1: 11.6
A2: Antal | B2: Typ | C2: Fabrikat | D2: Artikelnummer | E2: Typ | F2: Bil | G2: Årsmodell | H2: Var? | I2: Tillhörde / Ursprung Reg.nr | J2: Övrigt / Orsak / Skick | K2: EAN Codes | L2: I lagret 181212 | M2: Ligga kvar | N2: Borås | O2: Kontoret | P2: Leverantör | Q2: Kund / Verkstad | R2: Bokat upphämtning? | S2: KLART ? | T2: Tagen till Reg.nr / Ordernummer | U2: Göm / KLAR ? | V2: Övrigt | W2: Mått på paketet | X2: Övrigt 2 | Y2: Ta upp som lager 2018 | Z2: På lager 2023-12-31 | AA2: Inventering 2024-11-30 | AC2: Inköpspris | AD2: Till prislistan | AE2: Till prislistan
A3: 25 med reg nr nfr489. | B3: Elsatser | C3: STARC | E3: 7-polig | H3: Lager | K3: =IFNA(VLOOKUP(D3,'EAN Codes'!A:C,2,False),"") | U3: TRUE | Z3: FALSE
A4: 70 | B4: Dragkrokar | C4: Blandat | E4: S-kulor | F4: 2 st silver 1 guld. 2 bultade | H4: Kontoret | K4: =IFNA(VLOOKUP(D4,'EAN Codes'!A:C,2,False),"") | U4: TRUE | V4: Tagit en silver 5/9 -17 //TC | Z4: FALSE
A5: 15 | B5: Dragkrokar | D5: ZK-2 | F5: Adapterkula | H5: Lager | K5: =IFNA(VLOOKUP(D5,'EAN Codes'!A:C,2,False),"") | U5: TRUE | Z5: FALSE
A6: 971 | B6: Dragkrokar | C6: Steinhof | D6: A-037 | E6: Fast | F6: ALFA ROMEO 159 Sedan 2005> ALFA ROMEO 159 Kombi 2006> | G6: 2005> | H6: Linköping Speedy | K6: =IFNA(VLOOKUP(D6,'EAN Codes'!A:C,2,False),"") -> 5907615800986 | U6: TRUE | V6: Foaad klarade inte att montera den på OTH308. Ta hem krok. Skickad till HNE833 | Z6: FALSE
B7: Dragkrokar | C7: Steinhof | D7: A-042 | E7: AV | F7: ALFA ROMEO Giulietta Halvkombi 2010> | G7: 2010> | H7: Umeå | K7: =IFNA(VLOOKUP(D7,'EAN Codes'!A:C,2,False),"") -> 5907615801037 | U7: TRUE | V7: Tillhörde MXK761 som avbokat. Vänta ev med att ta hem detta draget. Se om kund bokar på. | Z7: FALSE
A8: 711 | B8: Motorvärmare | C8: DEFA | D8: 440052 | E8: Bluetooth Kit | F8: Alla bilar. Bluetooth Upgrade Kit | H8: Lager | I8: E2 | K8: =IFNA(VLOOKUP(D8,'EAN Codes'!A:C,2,False),"") | U8: TRUE | Z8: FALSE
A9: 878 | B9: Dragkrokar | C9: Westfalia | D9: 317114600001 | E9: Avtagbar | F9: Audi A1 2010> | H9: Lager | I9: D1 | K9: =IFNA(VLOOKUP(D9,'EAN Codes'!A:C,2,False),"") | U9: TRUE | Z9: FALSE
A10: 600 | B10: Dragkrokar | C10: Westfalia | D10: 317131 | E10: Fast | F10: Audi A3 , VW Golf , Seat Leon, Skoda | G10: 2012> | H10: Lager | I10: Kök | K10: =IFNA(VLOOKUP(D10,'EAN Codes'!A:C,2,False),"") | L10: Ja | U10: TRUE | V10: Till bil POW788 | Y10: x | Z10: FALSE
A11: 408 | B11: Dragkrokar | C11: Kovil | D11: 10023 | E11: fixed | F11: Audi A3 (8PA) 5D-Sportback 2WD | G11: 2004-9/2012 | H11: Lager | I11: B2 | K11: =IFNA(VLOOKUP(D11,'EAN Codes'!A:C,2,False),"") | L11: Ja | U11: TRUE | V11: GOK540 | Y11: x | Z11: FALSE
A12: 898 | B12: Dragkrokar | C12: Westfalia | D12: 321885 | E12: AV | F12: AUDI A3 04>13 3d Cab 2008> ej sportback VW Golf 5 , 5+ , 6 , 6+ , GTI , Cross | G12: 2005-2011 2011> | H12: Lager | I12: Stora rummet | K12: =IFNA(VLOOKUP(D12,'EAN Codes'!A:C,2,False),"") | U12: TRUE | Z12: FALSE
A13: 729 | B13: Bagagematta | C13: GJK | D13: 102030 | F13: Audi A3 2012 3-dörr | G13: 12> | H13: Lager | I13: A4 | K13: =IFNA(VLOOKUP(D13,'EAN Codes'!A:C,2,False),"") | U13: TRUE | Z13: FALSE
A14: 105 | C14: Westfalia | D14: 305299 | E14: Fast | F14: Audi A3 Sportback | G14: 2004>2013 | H14: Lagret | I14: B2 | K14: =IFNA(VLOOKUP(D14,'EAN Codes'!A:C,2,False),"") | U14: TRUE | Z14: FALSE
A15: 3 | C15: Westfalia | D15: 317132 | E15: AV | F15: Audi A3 Sportback | G15: 2012> | H15: Kontoret | I15: C3 | K15: =IFNA(VLOOKUP(D15,'EAN Codes'!A:C,2,False),"") | U15: TRUE | V15: Eklunds Bil 14/2 | Z15: FALSE
A16: 596 | B16: Dragkrokar | C16: Westfalia | D16: 305299 | E16: Fast | F16: Audi A3 Sportback | G16: 04>13 | H16: Lager | I16: TC | K16: =IFNA(VLOOKUP(D16,'EAN Codes'!A:C,2,False),"") | L16: Ja | U16: TRUE | V16: Tagen till KSX869 | Y16: x | Z16: FALSE
A17: 193 | C17: Steinhof | D17: V-063 | E17: Avtagbar | F17: Audi A3 Sportback | G17: 13> | H17: Lager | I17: A1 | K17: =IFNA(VLOOKUP(D17,'EAN Codes'!A:C,2,False),"") -> 5907615826146 | U17: TRUE | Z17: FALSE
A18: 192 | B18: Dragkrokar | C18: Steinhof | D18: A-067 | E18: Avtagbar | F18: Audi A3 Sportback | G18: 2004>2013 | H18: Lager | I18: A3 | K18: =IFNA(VLOOKUP(D18,'EAN Codes'!A:C,2,False),"") -> 5907615800573 | U18: TRUE | Z18: FALSE
A19: 459 | B19: Dragkrokar | C19: Westfalia | D19: 305299 | E19: Fast | F19: Audi A3 Sportback (8PA | G19: 2004>2013 | H19: Lager | I19: TC Kontor | K19: =IFNA(VLOOKUP(D19,'EAN Codes'!A:C,2,False),"") | L19: Ja | U19: TRUE | V19: KER358 | Y19: x | Z19: FALSE
A20: 450 | B20: Dragkrokar | C20: Westfalia | D20: 305299 | E20: Fast | F20: Audi A3 Sportback (8PA) | G20: 2004>2013 | H20: Lager | I20: B3 | K20: =IFNA(VLOOKUP(D20,'EAN Codes'!A:C,2,False),"") | L20: Ja | U20: TRUE | V20: MRS451 | Y20: x | Z20: FALSE
A21: 72 | C21: Westfalia | D21: 317132 | E21: Avtagbar | F21: Audi A3 Sportback / Sedan / Golf 7 / Golf Sportswan / Seat Leon Halvkombi / kombi / Skoda Octavia kombi / Halvkombi | G21: 12> | H21: Kontoret | I21: C3 | K21: =IFNA(VLOOKUP(D21,'EAN Codes'!A:C,2,False),"") | U21: TRUE | Z21: FALSE
A22: 571 | B22: Dragkrokar | C22: Westfalia | D22: 321885 | E22: AV | F22: Audi A3 Vw GOLF V | G22: 2003>2013 | H22: Lager | I22: TC | K22: =IFNA(VLOOKUP(D22,'EAN Codes'!A:C,2,False),"") | L22: Ja | U22: TRUE | Y22: x | Z22: FALSE
A23: 928 | B23: Dragkrokar | C23: Westfalia | D23: 317132 | E23: AV | F23: Audi A3, Audi Q2, Skoda Octavia, Seat Leon, VW Golf, VW T-Roc M FL | G23: 2012> | H23: Lager | I23: B1 | K23: =IFNA(VLOOKUP(D23,'EAN Codes'!A:C,2,False),"") | U23: TRUE | V23: OJG369 | Z23: FALSE
A24: 555 | B24: Dragkrokar | C24: Westfalia | D24: 321865 | E24: Fast | F24: Audi A3, VW Golf HB | G24: 2003>2013 | H24: Lager | I24: TC | K24: =IFNA(VLOOKUP(D24,'EAN Codes'!A:C,2,False),"") | U24: TRUE | V24: Tagen till VF97777 | Z24: FALSE
A25: 592 | B25: Dragkrokar | C25: Westfalia | D25: 321865 | E25: Fast | F25: Audi A3, VW Golf HB | G25: 03>13 | H25: Lager | I25: TC Kontor | K25: =IFNA(VLOOKUP(D25,'EAN Codes'!A:C,2,False),"") | L25: Ja | U25: TRUE | V25: KTZ082 | Y25: x | Z25: FALSE
B26: Dragkrokar | C26: Elsats | D26: Westfalia 305406300107 | E26: 7-pol | F26: Audi A3, VW Golf, Seat Leon, Skoda Octavia - passar många | G26: 2012> | H26: Lager | K26: =IFNA(VLOOKUP(D26,'EAN Codes'!A:C,2,False),"") | U26: TRUE | V26: Finns hos Halléns | Z26: FALSE
A27: 448 | B27: Dragkrokar | C27: Westfalia | D27: 305447 | E27: Avtagbar | F27: Audi A4 | G27: 2015> | H27: Lager | I27: B3 | K27: =IFNA(VLOOKUP(D27,'EAN Codes'!A:C,2,False),"") | L27: Ja | U27: TRUE | Y27: x | Z27: FALSE
A28: 869 | B28: Dragkrokar | C28: Witter | D28: AD44AQ | E28: Avtagbar | F28: Audi A4 | G28: 2005>2008 | H28: Äpplekullen | K28: =IFNA(VLOOKUP(D28,'EAN Codes'!A:C,2,False),"") -> 5060128530082 | U28: TRUE | V28: Tillhörde Xwe033 som avbokat monteringen. | Z28: FALSE
A29: 458 | B29: Dragkrokar | C29: Westfalia | D29: 305301 | E29: Fast | F29: Audi A4 | G29: 43198 | H29: Lager | I29: B3 | K29: =IFNA(VLOOKUP(D29,'EAN Codes'!A:C,2,False),"") | L29: Ja | U29: TRUE | V29: tagen till XUS797 | Y29: x | Z29: FALSE
A30: 527 | B30: Dragkrokar | C30: Steinhof | D30: A-053 | E30: Fast | F30: Audi A4 , Allroad, sedan m fl | G30: 2016> | H30: Lager | I30: C3 | K30: =IFNA(VLOOKUP(D30,'EAN Codes'!A:C,2,False),"") -> 5907615800450 | L30: Ja | U30: TRUE | V30: PJP624 | Y30: x | Z30: FALSE
A31: 389 | B31: Dragkrokar | C31: Kovil | D31: 10024 | E31: fixed | F31: Audi A4 (8K/B8) SDN/AVANT '08- | G31: 2008- | H31: Lager | I31: E1 | K31: =IFNA(VLOOKUP(D31,'EAN Codes'!A:C,2,False),"") | U31: TRUE | V31: NPL779 | Z31: FALSE
A32: 390 | B32: Dragkrokar | C32: Kovil | D32: 10024 | E32: fixed | F32: Audi A4 (8K/B8) SDN/AVANT '08- | G32: 2008- | H32: Lager | I32: E1 | K32: =IFNA(VLOOKUP(D32,'EAN Codes'!A:C,2,False),"") | U32: TRUE | V32: Till LWO919 | Z32: FALSE
A33: 412 | B33: Dragkrokar | C33: witter | D33: AD55Q | E33: Vertical | F33: AUDI A4 (B9) Sdn/Avant 2016- | G33: 2016- | H33: Lager | I33: D1 | K33: =IFNA(VLOOKUP(D33,'EAN Codes'!A:C,2,False),"") -> 5060128530259 | L33: Ja | U33: TRUE | V33: YTP188 | Y33: x | Z33: FALSE
A34: 554 | B34: Dragkrokar | C34: Westfalia | D34: 305301 | E34: Fast | F34: Audi A4 (kaross B7) | G34: 2004>2008 | H34: Lager | I34: TC | K34: =IFNA(VLOOKUP(D34,'EAN Codes'!A:C,2,False),"") | L34: Ja | U34: TRUE | V34: tagen till AEB410 | Y34: x | Z34: FALSE
A35: 607 | B35: Dragkrokar | C35: Westfalia | D35: 305445 | E35: AV | F35: Audi A4 / A5 | G35: 2007>2016 | H35: Lager | I35: HL kontor | K35: =IFNA(VLOOKUP(D35,'EAN Codes'!A:C,2,False),"") | U35: TRUE | Z35: FALSE
A36: 611 | B36: Dragkrokar | C36: Westfalia | D36: 305445 | E36: AV | F36: Audi A4 / A5 | G36: 2007>2016 | H36: Lager | I36: HL kontor | K36: =IFNA(VLOOKUP(D36,'EAN Codes'!A:C,2,False),"") | U36: TRUE | Z36: FALSE
A37: 161 | C37: Steinhof | D37: A-074 | E37: Fast | F37: Audi A4 A5 | G37: 07> | H37: Lager | I37: D2 | K37: =IFNA(VLOOKUP(D37,'EAN Codes'!A:C,2,False),"") -> 5907615800641 | U37: TRUE | Z37: FALSE
A38: 473 | B38: Dragkrokar | C38: Westfalia | D38: 305443 | E38: Fast | F38: Audi A4 Avant / Audi A5 | G38: 2007>2015 | H38: Lager | I38: TC Kontor | K38: =IFNA(VLOOKUP(D38,'EAN Codes'!A:C,2,False),"") | L38: Nej | U38: TRUE | Z38: FALSE
B39: Dragkrokar | C39: Witter | D39: AD48BQ | E39: AV | F39: Audi A4 B8 Sedan, estate 6.2008-.2015 | G39: 2008-.2015 | H39: Antingen här eller i Tyresö eller tagen?? | K39: =IFNA(VLOOKUP(D39,'EAN Codes'!A:C,2,False),"") | U39: TRUE | V39: Tillhörde LYK081 | Z39: FALSE
A40: 99 | B40: Dragkrokar | C40: Steinhof | D40: A-075 | E40: Avtagbar | F40: Audi A4 kombi | G40: 07> | H40: Lagret | I40: D1 | K40: =IFNA(VLOOKUP(D40,'EAN Codes'!A:C,2,False),"") -> 5907615800658 | U40: TRUE | Z40: FALSE
...

Sheet Våra Verkstäder
A1: Hur boka? | B1: Namn | C1: Lånebil | D1: Avtal | E1: Info om verkstad | F1: Kontaktperson | G1: Adress | J1: Telefonnummer | K1: E-post | M1: Org-nr | N1: Rabatt på beställningar | O1: Ansvarig hos B&J (förslag?) | P1: Skrift. Avtal? | Q1: Senast uppdaterade villkor | R1: Aktuell info, lediga tider mm? | S1: Aktiv | T1: Begränsningar | U1: Kan ta in husbilar | V1: Verkstadskontakter 3 | W1: Verkstadskontakter 4
B2: Car Care Sthlm AB | D2: 1600 kr exkl moms. (Han har fattat det som 1680 kr exkl moms) | F2: Daniel Johansson | G2: Örkroken 2 | H2: 138 40 | I2: Älta | J2: 08-41030038 | K2: info@carcare-sthlm.se | L2: =B2&" "&G2&" "&H2&" "&I2&" Telefon: "&J2 -> Car Care Sthlm AB Örkroken 2 138 40 Älta Telefon: 08-41030038 | O2: Tobias | Q2: 42614 | S2: Nej
B3: Vallentuna Däcktion AB | D3: 1600 kr exkl moms. | F3: Fredrik Faraj | G3: Moränvägen 1 | H3: 186 40 | I3: Vallentuna | J3: 070-0929723 | K3: vallentunadack@gmail.com | L3: =B3&" "&G3&" "&H3&" "&I3&" Telefon: "&J3 -> Vallentuna Däcktion AB Moränvägen 1 186 40 Vallentuna Telefon: 070-0929723 | O3: Tobias | Q3: 43070 | S3: Nej
B4: VTL Teknik | F4: Morgan | G4: Södra Orredsvägen 2 | H4: 439 74 | I4: Fjärås | J4: 072-325 56 86 | Q4: 42370 | S4: Nej
B5: Halléns Bilservice AB | D5: 1600 kr exkl moms | F5: Fredrik | G5: Kabelvägen 6 | H5: 553 02 | I5: Jönköping | J5: 070-285 81 69 | Q5: 42370 | S5: Nej | T5: B&J Skylt skickad 14/11
A6: Bjuda in i kalendern och även mail | B6: CE Motor | C6: Nej | D6: 2000 kr exkl moms. Övr. se ute i kanten | E6: Vill ha bilen 09.15 | F6: Christian | G6: Energivägen 2 | H6: 135 49 | I6: Tyresö | J6: 08-7703409 Christian 0707-397767 | K6: Christian@cemotor.se | L6: =B6&" "&G6&" "&H6&" "&I6&" Telefon: "&J6 -> CE Motor Energivägen 2 135 49 Tyresö Telefon: 08-7703409 Christian 0707-397767 | N6: Lämna 8.30 på morgonen Kan inte programmera. | O6: Frederik | Q6: 43864 | R6: Jobbar ej torsdag eller fredag i verkstaden. 10% ibland. | S6: Nej | T6: Bättre betalt vid fordonsspecifikt. Mer av kunden (i utgångspunkt) vid extra arbete såsom rost mm.
B7: S-Service Din Bilverkstad AB | D7: 1610 kr + moms /montering | F7: Savo | G7: Fjärestadsvägen 344 | H7: 253 42 | I7: Vallåkra | J7: 042-99208 | L7: =B7&" "&G7&" "&H7&" "&I7&" Telefon: "&J7 -> S-Service Din Bilverkstad AB Fjärestadsvägen 344 253 42 Vallåkra Telefon: 042-99208 | O7: Frederik | Q7: 42370 | S7: Nej
B8: Holmbergs Autoservice | D8: 1600 kr exkl moms. | F8: Markus | G8: Industrigatan 10 | H8: 273 35 | I8: Tomelilla | J8: 0738-133031 | K8: markus@holmbergsautoservice.se | L8: =B8&" "&G8&" "&H8&" "&I8&" Telefon: "&J8 -> Holmbergs Autoservice Industrigatan 10 273 35 Tomelilla Telefon: 0738-133031 | O8: Henrik | Q8: 42736 | S8: Nej
A9: Bjuda in i kalendern | B9: JHS Bilservice | C9: TRUE | D9: 1800 kr exkl moms. | E9: Vill helst ha bilen 09.00 Kan ta 2 bilar per dag. | F9: Jack | G9: Jättevägen 4 | H9: 17677 | I9: Järfälla | J9: 08-58352820 (JACK) 070-881 67 98 | K9: jhs.dragkrok@gmail.com | L9: =B9&" "&G9&" "&H9&" "&I9&" Telefon: "&J9 -> JHS Bilservice Jättevägen 4 17677 Järfälla Telefon: 08-58352820 (JACK) 070-881 67 98 | N9: Fri frakt -10% på dragen | O9: Håkan | P9: FALSE | Q9: 46057 | R9: Nöjd med samarbetet, har mycket att göra i verkstaden - boka ca 1.5 vecka fram | S9: Ja | U9: TRUE
B10: Motornavet | C10: TRUE | D10: 1600 kr exkl moms. | F10: Niklas | G10: Varholmsgatan 12 | H10: 414 74 | I10: Göteborg | J10: 031-128117 | K10: info@motornavet.se | N10: Fri frakt -10% på dragen | O10: Håkan | P10: FALSE | Q10: 42370 | S10: Nej | U10: FALSE
B11: 414 Industries | C11: TRUE | D11: 1600 kr exkl moms. | F11: Ola | H11: 414 74 | I11: Göteborg | J11: 072-7268393 | K11: ola.svalander@gmail.com | L11: =B11&" "&G11&" "&H11&" "&I11&" Telefon: "&J11 -> 414 Industries 414 74 Göteborg Telefon: 072-7268393 | N11: Fri frakt -10% på dragen | O11: Håkan | P11: FALSE | Q11: 42979 | S11: NEJ | U11: FALSE
B12: Tistings Träförädling | C12: TRUE | F12: Oskar | N12: Fri frakt -10% på dragen | O12: Håkan | P12: FALSE | Q12: 42370 | S12: Nej | U12: FALSE
A13: Bjuda in i kalendern | B13: Supreme Autoservice | C13: TRUE | D13: 2250 kr exkl moms Fordonsspecifik 800 ex moms extra om den är jobbig. Extra matarsats 800 ex moms extra. Udda bilar, lyxbilar diskuteras innan. | E13: Vill ha bilen 08.00 Boka upp 3 timmar i kalendern | F13: Ilker | G13: Cypressvägen 10 | H13: 213 63 | I13: Malmö | J13: 040-213 580 ILKER: 0736-600974 | K13: info@supremeauto.se | L13: =B13&" "&G13&" "&H13&" "&I13&" Telefon: "&J13 -> Supreme Autoservice Cypressvägen 10 213 63 Malmö Telefon: 040-213 580 ILKER: 0736-600974 | N13: Fri frakt -10% på dragen | O13: Håkan | P13: FALSE | Q13: 42370 | R13: Nöjd med samarbetet, har mycket att göra i verkstaden - boka ca 1.5 vecka fram | S13: Ja | U13: FALSE
A14: Bjuda in i kalendern och även mail | B14: Tågaborgs Bilservice | C14: TRUE | D14: 2500 kr exkl moms | E14: Öppnar 07.00 och stänger 16.30 | F14: Jonas och Hacim | G14: Florettgatan 7 | H14: 254 67 | I14: Helsingborg | J14: 042-201804 | K14: jonas@tagaborgsbil.com hacim@tagaborgsbil.com info@tagaborgsbil.com | L14: =B14&" "&G14&" "&H14&" "&I14&" Telefon: "&J14 -> Tågaborgs Bilservice Florettgatan 7 254 67 Helsingborg Telefon: 042-201804 | N14: Fri frakt -10% på dragen | O14: Håkan | P14: FALSE | Q14: 43591 | S14: Nej | T14: Pratar med Jonas om att kontrollera dragkrokar innan montering. Bra samtal. Han nämnde även priser, och var överrens om att det är dumt att ändra något nu i svajig marknad. Men prata till hösten igen om kanske 2000 kr + moms för monteringarna (hans förslag) | U14: FALSE
B15: Motala Bilpartner | C15: TRUE | F15: Denis | G15: Vintergatan 4 | H15: 591 32 | I15: Motala | J15: 0141-55990 | N15: Fri frakt -10% på dragen | O15: Håkan | P15: FALSE | Q15: 42370 | S15: Nej | U15: FALSE
A16: Ringa och boka med Sanel | B16: Williams Garage | C16: FALSE | D16: 1600 kr exkl moms (kan komma att höjas) | E16: Vill ha bilen 08.00 | F16: Sanel | G16: Förrådsgatan 10 | H16: 542 35 | I16: Mariestad | J16: 0737-266323 | K16: info@williamsgarage.se | L16: =B16&" "&G16&" "&H16&" "&I16&" Telefon: "&J16 -> Williams Garage Förrådsgatan 10 542 35 Mariestad Telefon: 0737-266323 | N16: Fri frakt -10% på dragen | O16: Håkan | P16: FALSE | Q16: 46057 | R16: Mailat och återkommer om prisbild | S16: Nej | U16: FALSE
A17: Ring innan om tid! | B17: AB Ystad Meck & Däck | C17: TRUE | D17: 2000 kr exkl moms. | E17: Vill ha bilen 08.00 | F17: Marcus | G17: Mässingsgatan 9 | H17: 271 39 | I17: Ystad | J17: 0411-72422 | K17: verkstad@ystaddack.se | L17: =B17&" "&G17&" "&H17&" "&I17&" Telefon: "&J17 -> AB Ystad Meck & Däck Mässingsgatan 9 271 39 Ystad Telefon: 0411-72422 | N17: Fri frakt -10% på dragen | O17: Håkan | P17: FALSE | Q17: 46057 | R17: Nöjd med samarbetet, har mycket att göra i verkstaden - boka ca 2.5 vecka fram och ring före bokning | S17: Ja | U17: FALSE
A18: Bjud in i kalendern | B18: IM Bilservice | C18: TRUE | D18: Dragkrok: 2400 kr + moms Motorvärmare: 2000 kr + moms | E18: Vill ha bilen 08.00. | F18: Issam | G18: Kvällsvindsgatan 6 | H18: 652 21 | I18: Karlstad | J18: 054-85 68 70 | K18: imbilservice@boschcarservice.se samassaad5@gmail.com | L18: =B18&" "&G18&" "&H18&" "&I18&" Telefon: "&J18 -> IM Bilservice Kvällsvindsgatan 6 652 21 Karlstad Telefon: 054-85 68 70 | N18: Fri frakt -10% på dragen | O18: Håkan | P18: FALSE | Q18: 46057 | R18: Fortsätter sammarbetet men tar krokarna ifrån Experten tyvärr efter strul med 3 st leveranser Boka 1,5 vecka fram | S18: Ja | U18: FALSE
B19: Frösö Gummi AB | C19: TRUE | F19: Fredrik | G19: Frösövägen 63 | H19: 832 44 | I19: FRÖSÖN | J19: 063-104666 | N19: Fri frakt -10% på dragen | O19: Håkan | P19: FALSE | Q19: 42736 | S19: Nej | U19: FALSE
B20: HH Bilservice HB | C20: TRUE | D20: 1600 kr exkl moms. | F20: Fredrik Faraj | G20: Jättevägen 4 | H20: 176 77 | I20: Järfälla | J20: 08-58352820 | N20: Fri frakt -10% på dragen | O20: Håkan | P20: FALSE | Q20: 42614 | S20: Nej | U20: FALSE
A21: Bjuda in i kalendern och även mail maila först och kolla läget | B21: Speedy Bilservice Åhus (Åhus Fordonsteknik AB) | C21: FALSE | D21: 2500kr exkl moms. | E21: Vill ha bilen 08.00. | F21: Robin och Alex | G21: Koriandervägen 4 | H21: 296 41 | I21: Åhus | J21: 044-24 00 57 | K21: ahus@speedybilservice.se | L21: =B21&" "&G21&" "&H21&" "&I21&" Telefon: "&J21 -> Speedy Bilservice Åhus (Åhus Fordonsteknik AB) Koriandervägen 4 296 41 Åhus Telefon: 044-24 00 57 | N21: Fri frakt -10% på dragen | O21: Håkan | P21: FALSE | Q21: 46057 | R21: Mycket jobb just nu så vi mailar om bokning Ändrat till 2500+ moms. Snackat även om clipps sats till inredning som går sönder vid demontering, att det framgår till kund att det kostar extra ex 500kr | S21: Ja | U21: FALSE
B22: Brännlunds Garage | D22: 1600 kr exkl moms. | F22: Peter | G22: Snäppvägen 3 | H22: 802 91 | I22: Gävle | J22: 0703-980894 | K22: info@brannlundsgarage.com | L22: =B22&" "&G22&" "&H22&" "&I22&" Telefon: "&J22 -> Brännlunds Garage Snäppvägen 3 802 91 Gävle Telefon: 0703-980894 | N22: Fri frakt -10% på dragen | O22: Håkan | P22: FALSE | Q22: 42887 | S22: Nej | U22: FALSE
A23: Maila och ringa | B23: Magnus Snabbservice | D23: 2000 kr exkl moms. | E23: Vill ha bilen 08.00 | F23: Magnus och Daniel | G23: Skallebackavägen 20 | H23: 302 41 | I23: Halmstad | J23: 035-10 00 55 0733-854120 | K23: info@magnussnabbservice.se magnus@magnussnabbservice.se fredrik@magnussnabbservice.se | L23: =B23&" "&G23&" "&H23&" "&I23&" Telefon: "&J23 -> Magnus Snabbservice Skallebackavägen 20 302 41 Halmstad Telefon: 035-10 00 55 0733-854120 | N23: Fri frakt -10% på dragen | O23: Håkan | P23: FALSE | Q23: 43490 | S23: Nej | U23: FALSE
B24: Pettsons Bilservice | D24: 2000 kr exkl moms. | F24: Agne | G24: Västerhejde Gamla Kyrkvägen 8 | H24: 622 61 | I24: Visby | J24: 0706-296146 | N24: Fri frakt -10% på dragen | O24: Håkan | P24: FALSE | Q24: 42370 | S24: Nej | U24: FALSE
A25: Bjuda in i kalendern och även mail | B25: Speedy Bilservice Falkenberg | C25: 195 | D25: 2300 kr exkl moms. | E25: Vill ha bilen 08.00 helst | F25: Andreas | G25: Oktanvägen 1c | H25: 311 32 | I25: Falkenberg | J25: 0346-216969 0705-880519 | K25: falkenberg@speedybilservice.se | L25: =B25&" "&G25&" "&H25&" "&I25&" Telefon: "&J25 -> Speedy Bilservice Falkenberg Oktanvägen 1c 311 32 Falkenberg Telefon: 0346-216969 0705-880519 | N25: Fri frakt -10% på dragen | O25: Håkan | P25: FALSE | Q25: 43496 | S25: Nej | U25: FALSE
B26: Bil och Maskinteknik AB | D26: 1600 kr exkl moms. | F26: Magnus, Mikael | G26: Ahlmarksvägen 1 | H26: 953 36 | I26: Haparanda | J26: 072-2197848 | K26: 34009@okq8bilverkstad.se | L26: =B26&" "&G26&" "&H26&" "&I26&" Telefon: "&J26 -> Bil och Maskinteknik AB Ahlmarksvägen 1 953 36 Haparanda Telefon: 072-2197848 | N26: Fri frakt -10% på dragen | O26: Håkan | P26: FALSE | Q26: 43490 | S26: Nej | T26: De jobbar bara en i verkstaden nu, den andra i gruvan. Kör varannan vecka. //TC 3/11 | U26: FALSE
A27: Bjuda in i kalendern | B27: Drakängens Bilservice | C27: TRUE | D27: 1600 kr exkl moms. | E27: Vill ha bilen 08.00. | F27: Robban | G27: Drakängen Attsjö | H27: 36593 | I27: Furuby/växjö | J27: 0704-644547 | K27: robban300zx@hotmail.com | L27: =B27&" "&G27&" "&H27&" "&I27&" Telefon: "&J27 -> Drakängens Bilservice Drakängen Attsjö 36593 Furuby/växjö Telefon: 0704-644547 | N27: Fri frakt -10% på dragen | O27: Håkan | P27: FALSE | Q27: 46057 | R27: Nöjd med samarbetet, har mycket att göra i verkstaden - boka ca 1.5 vecka fram sem 26/4 - 2 veckor | S27: Ja | U27: FALSE
A28: Bjuda in i kalendern | B28: JV Automontage | C28: 295 kr (vår egen) | D28: 1800 kr exkl moms | E28: Vill ha bilen 09.15 | F28: Jesper Vinquist | G28: EA Rosengrens gata 27 | H28: 421 32 | I28: Västra Frölunda | J28: 0735-180195 | K28: jesper@jvautomontage.se | L28: =B28&" "&G28&" "&H28&" "&I28&" Telefon: "&J28 -> JV Automontage EA Rosengrens gata 27 421 32 Västra Frölunda Telefon: 0735-180195 | N28: Fri frakt -10% på dragen | O28: Håkan | P28: FALSE | Q28: 43617 | S28: Nej | U28: FALSE
B29: Speedy Bilservice Karlskrona | D29: 1600 kr exkl moms. | F29: Nikki | G29: Sunnavägen 99 | H29: 371 41 | I29: Karlskrona | J29: 0455-192 20 | K29: karlskrona@speedybilservice.se | L29: =B29&" "&G29&" "&H29&" "&I29&" Telefon: "&J29 -> Speedy Bilservice Karlskrona Sunnavägen 99 371 41 Karlskrona Telefon: 0455-192 20 | N29: Fri frakt -10% på dragen | O29: Håkan | P29: FALSE | Q29: 43490 | S29: NEJ | U29: FALSE
A30: Lägga in i kalendern | B30: Äpplekullen Bil & Däckservice | C30: TRUE | D30: 2000 kr exkl moms. | E30: Vill ha bilen 08.00 | F30: Roger (Marcus & Mikael) | G30: Ekenleden 1 | H30: 428 36 | I30: Kållered | J30: 031-7951000 (0735-361705) | K30: info@applekullen.se | L30: =B30&" "&G30&" "&H30&" "&I30&" Telefon: "&J30 -> Äpplekullen Bil & Däckservice Ekenleden 1 428 36 Kållered Telefon: 031-7951000 (0735-361705) | N30: Fri frakt -10% på dragen | O30: Håkan | P30: FALSE | Q30: 46057 | R30: "Nöjd med samarbetet, har mycket att göra i verkstaden - boka ca 2 veckor fram | S30: Ja | U30: TRUE
A31: Skicka info på SMS. | B31: Widhedens Bil AB | D31: 1600 kr exkl moms 10% när han handlar | E31: Vill ha bilen 08.00 | F31: Richard | G31: Björbäcksvägen 6 | H31: 451 55 | I31: Uddevalla | J31: 0763-048909(Widhedens) 0738-219725(Richard) | K31: widhedenbil@gmail.com | L31: =B31&" "&G31&" "&H31&" "&I31&" Telefon: "&J31 -> Widhedens Bil AB Björbäcksvägen 6 451 55 Uddevalla Telefon: 0763-048909(Widhedens) 0738-219725(Richard) | N31: Fri frakt -10% på dragen | O31: Håkan | P31: FALSE | Q31: 44222 | S31: Nej | U31: FALSE
A32: Skicka info på SMS. | B32: 1st Class Bil & Lackering | D32: 1600 kr exkl moms 10% när han handlar | F32: Ivar | G32: Skälebol Mossen 1 | H32: 464 92 | I32: Mellerud | J32: 0764-14 25 66 | K32: Ivar.Borresen2022@outlook.com | L32: =B32&" "&G32&" "&H32&" "&I32&" Telefon: "&J32 -> 1st Class Bil & Lackering Skälebol Mossen 1 464 92 Mellerud Telefon: 0764-14 25 66 | N32: Fri frakt -10% på dragen | O32: Håkan | P32: FALSE | Q32: 44208 | S32: Nej | T32: Meddelat 23/1 att han ej kan fakturera längre och därmed inte kan montera. | U32: FALSE
B33: Nybrons Bilservice AB | D33: 1600 kr exkl moms. | F33: Roger | G33: Bergslenagatan 49 | H33: 506 30 | I33: Borås | J33: 033-131780 | K33: info@nybronsbilservice.se | L33: =B33&" "&G33&" "&H33&" "&I33&" Telefon: "&J33 -> Nybrons Bilservice AB Bergslenagatan 49 506 30 Borås Telefon: 033-131780 | N33: Fri frakt -10% på dragen | O33: Håkan | P33: FALSE | Q33: 43503 | S33: Nej | U33: FALSE
B34: Bilverkstan i Sundsvall AB | D34: 1600 kr exkl moms. | F34: Kent-Ove Nordin | G34: Tegelvägen 8B | H34: 853 50 | I34: Sundsvall | J34: 070-330 24 11 | K34: nordan@bilverkstanisundsvall.se | L34: =B34&" "&G34&" "&H34&" "&I34&" Telefon: "&J34 -> Bilverkstan i Sundsvall AB Tegelvägen 8B 853 50 Sundsvall Telefon: 070-330 24 11 | N34: Fri frakt -10% på dragen | O34: Håkan | P34: FALSE | Q34: 43501 | S34: Nej | U34: FALSE
B35: Speedy Bilservice Jönköping | D35: 1600 kr exkl moms. | F35: Ivan | G35: Bangårdsgatan 4 | H35: 553 03 | I35: Jönköping | J35: 036-2913000 | K35: jonkoping@speedybilservice.se | L35: =B35&" "&G35&" "&H35&" "&I35&" Telefon: "&J35 -> Speedy Bilservice Jönköping Bangårdsgatan 4 553 03 Jönköping Telefon: 036-2913000 | N35: Fri frakt -10% på dragen | O35: Håkan | P35: FALSE | Q35: 43475 | S35: Nej | U35: FALSE
B36: Speedy Bilservice Östermalm | D36: 1600 kr exkl moms. 3000kr + moms ska dem ha //TC | F36: Gleb | G36: Valhallavägen 161 Mitt emot Fältöversten. T-station 15 m. | H36: 115 53 | I36: Stockholm | J36: 08-662 60 65 0736-974541 | K36: ostermalm@speedybilservice.se | L36: =B36&" "&G36&" "&H36&" "&I36&" Telefon: "&J36 -> Speedy Bilservice Östermalm Valhallavägen 161 Mitt emot Fältöversten. T-station 15 m. 115 53 Stockholm Telefon: 08-662 60 65 0736-974541 | N36: Fri frakt -10% på dragen | O36: Håkan | P36: FALSE | Q36: 43525 | S36: NEJ | U36: FALSE
A37: Bjuda in i kalendern och även mail | B37: Sjömarkens Motor & Aluminium | C37: FALSE | D37: 2500 kr exkl moms | E37: Vill ha bilen 08.00 | F37: Jonas | G37: Göteborgsvägen 25 | H37: 51840 | I37: Sjömarken/Borås | J37: 070-9296019 | K37: info@aluminiumiboras.se | L37: =B37&" "&G37&" "&H37&" "&I37&" Telefon: "&J37 -> Sjömarkens Motor & Aluminium Göteborgsvägen 25 51840 Sjömarken/Borås Telefon: 070-9296019 | N37: Fri frakt -10% på dragen | O37: Håkan | P37: FALSE | Q37: 46057 | R37: """Nöjd med samarbetet, har lagomt att göra i verkstaden - boka ca 1,5 veckor fram " | S37: Ja | U37: FALSE
A38: Maila och ev SMS:a han | B38: Skarstad Bilverkstad // Daniel Bergendahl | C38: FALSE | D38: 1600 kr exkl moms. | E38: Vill ha bilen kl 10.00 och Tisdagar, andra dagar får vi ringa om | F38: Daniel | G38: Basegården 11 Skarstad | H38: 53495 | I38: Vara | J38: 0707-589796 | K38: turbomani1@hotmail.com | L38: =B38&" "&G38&" "&H38&" "&I38&" Telefon: "&J38 -> Skarstad Bilverkstad // Daniel Bergendahl Basegården 11 Skarstad 53495 Vara Telefon: 0707-589796 | N38: Fri frakt -10% på dragen | O38: Håkan | P38: FALSE | Q38: 43490 | S38: Ja | U38: FALSE
B39: Skäggetorps Bilverkstad | D39: 1600 kr exkl moms. | F39: Foaad Daniel | G39: Skäggetorp Centrum 8 | H39: 586 44 | I39: Linköping | J39: 013-17 16 18 076-225 09 11 | K39: foaad_daniel@hotmail.com | L39: =B39&" "&G39&" "&H39&" "&I39&" Telefon: "&J39 -> Skäggetorps Bilverkstad Skäggetorp Centrum 8 586 44 Linköping Telefon: 013-17 16 18 076-225 09 11 | N39: Fri frakt -10% på dragen | O39: Håkan | P39: FALSE | Q39: 43525 | S39: NEJ | U39: FALSE
B40: Speedy Bilservice Tagene | D40: 1600 kr exkl moms. | F40: Jonas | G40: Karlsbogårdsgatan 2 (samma hus som Besikta) | H40: 425 37 | I40: Hising Kärra | J40: 031-57 11 99 | L40: =B40&" "&G40&" "&H40&" "&I40&" Telefon: "&J40 -> Speedy Bilservice Tagene Karlsbogårdsgatan 2 (samma hus som Besikta) 425 37 Hising Kärra Telefon: 031-57 11 99 | N40: Fri frakt -10% på dragen | O40: Håkan | P40: FALSE | Q40: 43525 | S40: NEJ | U40: FALSE
...

Sheet Nykontakt
A1: Datum | B1: Verkstad | C1: Kommentar | D1: Kontaktperson | E1: Adress | F1: Postnr | G1: Ort | H1: Telefonnummer | I1: E-post | K1: Org-nr | L1: Övrigt | M1: Ansvarig hos B&J (förslag?) | N1: Skrift. Avtal? | O1: Datum | P1: Aktuell info, lediga tider mm? | Q1: Aktiv | R1: Verkstadskontakter 1 | S1: Verkstadskontakter 2 | T1: Verkstadskontakter 3 | U1: Verkstadskontakter 4
A2: 2026-01-20 2026-02-03 | B2: Kennys Bilverkstad Vemdalen | C2: samtal och mail återkommer om mont pris
A3: 2026-01-21 2026-02-03 | B3: Mekonomen Årjäng | C3: samtal och mail återkommer om mont pris
A4: 46043 | B4: Berners Person - och Transportbilar | C4: mailat
A5: 46043 | B5: Bilhuset Småland AB | C5: mailat
A6: 46043 | B6: Fryksdalens Bil AB | C6: Mailat
A7: 46043 | B7: Autovision sverige ab | C7: Mailat
A8: 46043 | B8: Bromma bilanalys & Bilverkstad AB | C8: Mailat
A9: 46043 | B9: Bil Brodd AB | C9: Mailat
A10: 46043 | B10: MCS Sverige AB / Dunhoffbil | C10: Mailat
A11: 46043 | B11: Ljusdals Bilverkstad AB | C11: Mailat
A12: 46043 | B12: Roberts Verkstad | C12: Mailat
A13: 46043 | B13: Dannes AutoMotor AB | C13: Mailat
A14: 46043 | B14: Vinsta Bilservice AB | C14: Mailat
A15: 46043 | B15: Via Bilservice AB | C15: Mailat
... A24: 46051 | B24: Fastmec AB meka Ludvika | C24: telefon,mail återkommer om pris
A25: 46056 | B25: Williams Garage | C25: Mailat om prisfråga | D25: Sanel
A26: 46056 | B26: BNM Bilverkstad AB | C26: Sänkte priset till 2800+m | D26: Benon
A27: 46056 | B27: PS Motorsport 070-555 14 46 | C27: Mailat | D27: Patrik
A28: 46070 | B28: Enarsson bil och plåt | C28: telefon,mail
A29: 46070 | B29: Total bil i Falun | C29: Mailat ,besökt
A30: 46070 | B30: Salabilteknik Q8 | C30: Besökt | D30: Patrik
A31: 46070 | B31: Bilkompaniet Sala Volvo | C31: Besökt | D31: Jan
A32: 46070 | B32: Nordiska Bilkompaniet AB | C32: Besökt partner | D32: Hozan
A33: 46070 | B33: Norrmans bil Sala | C33: Besökt
A34: 46070 | B34: Sala bilservice | C34: Besökt
A35: 46070 | B35: AD Butik i Sala | C35: Besökt
A36: 46070 | B36: Mekonomen Butik Sala | C36: Besökt
A37: 46070 | B37: Möller bil Sala VW | C37: Besökt
A38: 46071 | B38: PA Bil & Motor Karlskoga | C38: Ringt/Mailat | D38: Sanna | H38: 0586-531 70
A39: 46072 | B39: Plåt & Mek Fagersta AB | C39: Besökt och blir partnerverkstad | D39: Alexandar | H39: 0223 - 211 11
A40: 46072 | B40: Autocenter i bergslagen AB BDS | C40: besökt | H40: 0223 14280
A41: 46072 | B41: Bilcity i Fagersta Kia | C41: besökt | D41: Stefan | H41: 0223 16170
A42: 46072 | B42: Motorforum i Fagersta | C42: besökt
A43: 46072 | B43: Luddes Hyresmaskiner | C43: besökt smsat 070 3195000 | D43: Ludde | H43: 0223 10900
A44: 46079 | B44: idrefordonsservice | C44: Besökt och blir partnerverkstad | H44: 073-061 62 91
A45: 46083 | B45: NK MEK & TUNING AB | C45: telefon /mail partner | H45: 0652-108 88 | K45: 5594077306
A46: 46083 | B46: Fordonsservice Uppland AB | C46: Telefon/mail Partner | H46: 073 767 03 11
A47: 46084 | B47: Motorbolaget i Växjö AB störst på a-traktorer | C47: Telefon /mail | H47: 0470 - 131 80
A48: 46085 | B48: Smista bil mekonomen | C48: Telefon /mail | H48: 08 55036550
...

Sheet Tilläggstjänster
A1: Förslag tilläggstjäster | B1: Prisförslag mot kund | C1: Fakturerat belopp

Sheet Leverantörer
A1: supplier_number | B1: organisation_number | C1: name | D1: invoice_address | E1: invoice_address2 | F1: invoice_zip_code | G1: invoice_city | H1: invoice_country_code | I1: invoice_country | J1: Aktiv | K1: Bör avtal finnas ? | L1: Avtal
A2: 1 | B2: 5591025852 | C2: Sendify AB | D2: Volrat Thamsgatan 4 | F2: 41260 | G2: Göteborg | H2: SE | I2: Sverige | J2: TRUE | K2: FALSE
A3: 2 | C3: MARTEC Automotive Sp. z o.o. | D3: al. M.B Fatimskiej 16 | F3: 33-100 | G3: Tarnów | H3: PL | I3: Poland | J3: TRUE | K3: FALSE
A4: 3 | B4: 6827593036 | C4: Steinhof | D4: Przemysłowa 27A | F4: 33-100 | G4: Tarnow | H4: PL | I4: Poland | J4: TRUE | K4: FALSE
A5: 4 | B5: 30687388 | C5: Bertelshofer GmbH | D5: Glockenbecherstraße 6 | F5: 86706 | G5: Weichering | H5: DE | I5: Germany | J5: FALSE | K5: FALSE
A6: 5 | B6: 5561094532 | C6: UPS AB | D6: Elektronikhöjden 6 | F6: 17543 | G6: JÄRFÄLLA | H6: SE | I6: Sverige | J6: FALSE | K6: FALSE
A7: 6 | C7: Folksam | D7: Box 53300 | F7: 40016 | G7: Göteborg | H7: SE | I7: Sverige | J7: FALSE | K7: FALSE
A8: 7 | B8: 5568170707 | C8: Reservdelshörnan i Sisjön AB | D8: Sörbyvägen 29 | F8: 47172 | G8: HJÄLTEBY | H8: SE | I8: Sverige | J8: FALSE | K8: FALSE
A9: 8 | B9: 5564300142 | C9: Telia Sverige | F9: 12386 | G9: FARSTA | H9: SE | I9: Sverige | J9: FALSE | K9: FALSE
A10: 9 | B10: 5562675164 | C10: TELE2 FÖRETAG | D10: Box 62 | F10: 16494 | G10: KISTA | H10: SE | I10: Sverige | J10: TRUE | K10: FALSE
A11: 10 | B11: 5569462129 | C11: Tistings Träförädling AB | D11: Sågbacken 6 | F11: 69450 | G11: VRETSTORP | H11: SE | I11: Sverige | J11: FALSE | K11: FALSE
A12: 11 | B12: 5568163637 | C12: HA Transport AB | D12: Växthusvägen 3 | F12: 45175 | G12: UDDEVALLA | H12: SE | I12: Sverige | J12: FALSE | K12: FALSE
A13: 12 | B13: 5566748066 | C13: Bilcentrum i Umeå AB | D13: Norra Obbolavägen 114 | F13: 90422 | G13: UMEÅ | H13: SE | I13: Sverige | J13: TRUE | K13: FALSE
A14: 13 | B14: 9697382480 | C14: Spånga Bensin & Service Handelsbolag | D14: Täbylundsvägen 63 | F14: 16347 | G14: SPÅNGA | H14: SE | I14: Sverige | J14: FALSE | K14: FALSE
A15: 14 | B15: 5567343040 | C15: Monoflex Nordic AB | D15: Box 14 | F15: 73425 | G15: HALLSTAHAMMAR | H15: SE | I15: Sverige | J15: FALSE | K15: FALSE
A16: 15 | B16: 5567884415 | C16: Äpplekullens Bil & Däckservice | D16: Ekenleden 1 | F16: 42836 | G16: KÅLLERED | H16: SE | I16: Sverige | J16: TRUE | K16: FALSE
A17: 16 | B17: 6708215055 | C17: VTL Teknik | D17: Södra Orredsvägen 2 | F17: 43974 | G17: Fjärås | J17: FALSE | K17: FALSE
A18: 17 | B18: 5567614960 | C18: Nets Sweden AB | D18: Box 778 | F18: 13124 | G18: NACKA | H18: SE | I18: Sverige | J18: TRUE | K18: FALSE
A19: 18 | B19: 5020077862 | C19: Svenska Handelsbanken AB | F19: 10670 | G19: STOCKHOLM | H19: SE | I19: Sverige | J19: FALSE | K19: FALSE
A20: 19 | B20: 5566103429 | C20: Blocket / Svea Ekonomi | F20: 16981 | G20: Stockholm | J20: FALSE | K20: FALSE
A21: 20 | B21: 5164074709 | C21: DIBS Payment Services AB | D21: Box 165 | F21: 10123 | G21: STOCKHOLM | H21: SE | I21: Sverige | J21: FALSE | K21: FALSE
A22: 21 | B22: 8024657119 | C22: Radio 88 | D22: Royne Nilsson, Box 140 | F22: 43908 | G22: FRILLESÅS | H22: SE | I22: Sverige | J22: FALSE | K22: FALSE
A23: 22 | B23: 2021006099 | C23: Transportstyrelsen | F23: 70195 | G23: Örebro | J23: FALSE | K23: FALSE
A24: 23 | B24: 5565185989 | C24: Svensk Betalningskontroll AB | D24: Box 9085 | F24: 40092 | G24: GÖTEBORG | H24: SE | I24: Sverige | J24: FALSE | K24: FALSE
A25: 24 | C25: Watling Engineers LTD. | D25: 88 Park Street Village | F25: AL2 2LR | G25: Herts | H25: GB | I25: United Kingdom | J25: FALSE | K25: FALSE
A26: 25 | B26: 5565861472 | C26: Textalk AB | D26: Krokslätts Fabriker 12 | F26: 43137 | G26: MÖLNDAL | H26: SE | I26: Sverige | J26: FALSE | K26: FALSE
A27: 26 | B27: 5566307806 | C27: City Network Hosting AB | D27: Borgmästaregatan 18 | F27: 37134 | G27: KARLSKRONA | H27: SE | I27: Sverige | J27: FALSE | K27: FALSE
A28: 27 | B28: 5569889743 | C28: Fordonsteknik Jönköping AB | D28: Herkulesvägen 16 | F28: 55303 | G28: JÖNKÖPING | H28: SE | I28: Sverige | J28: FALSE | K28: FALSE
A29: 28 | B29: 5564696291 | C29: Fortnox Aktiebolag | D29: Box 427 | F29: 35106 | G29: VÄXJÖ | H29: SE | I29: Sverige | J29: TRUE | K29: FALSE
A30: 29 | B30: 5702133215 | C30: Pettsons Bilservice | D30: VÄSTERHEJDE GAMLA KYRKVÄGEN 8 | F30: 62261 | G30: VISBY | H30: SE | I30: Sverige | J30: FALSE | K30: FALSE
A31: 30 | B31: 9112031019 | C31: Berglunds Montage | D31: Hagagatan 6 F | F31: 79430 | G31: Orsa | H31: SE | I31: Sverige | J31: FALSE | K31: FALSE
A32: 31 | B32: 5567977888 | C32: Möllerstrand Service AB | D32: Vidkärrsgatan 28 | F32: 41672 | G32: GÖTEBORG | H32: SE | I32: Sverige | J32: FALSE | K32: FALSE
A33: 32 | B33: 5569340424 | C33: Modifinder AB | D33: Stortorget 27 | F33: 21134 | G33: MALMÖ | H33: SE | I33: Sverige | J33: FALSE | K33: FALSE
A34: 33 | B34: 5590054523 | C34: Motornavet Göteborg AB | D34: Varholmsgatan 12 | F34: 41474 | G34: GÖTEBORG | H34: SE | I34: Sverige | J34: FALSE | K34: FALSE
A35: 34 | B35: 5164029257 | C35: FedEx | D35: Box 94 | F35: 19045 | G35: STOCKHOLM-ARLANDA | H35: SE | I35: Sverige | J35: FALSE | K35: FALSE
A36: 35 | B36: 5590429386 | C36: Supreme Autoservice i Malmö AB | D36: Cypressvägen 10 | F36: 21363 | G36: MALMÖ | H36: SE | I36: Sverige | J36: TRUE | K36: FALSE
A37: 36 | B37: 5564306578 | C37: EM Motor AB | D37: Karl Johansg. 146 | F37: 41451 | G37: GÖTEBORG | H37: SE | I37: Sverige | J37: FALSE | K37: FALSE
... A41: 40 | B41: 5566081716 | C41: Unifaun AB | D41: Box 2326 | F41: 40315 | G41: GÖTEBORG | H41: SE | I41: Sverige | J41: FALSE | K41: FALSE
A42: 41 | B42: 110/251/00567 | C42: M&L Automobile | D42: Delitzscher Str. 51 | F42: D-06112 | G42: Halle | H42: DE | I42: Germany | J42: FALSE | K42: FALSE
A43: 42 | C43: Felparkering Transportstyrelsen | J43: FALSE | K43: FALSE
...

Sheet Lager elsatser
A1: No. | B1: Tillverkare | C1: 7-/13-pol | D1: Artikelnummer | E1: Bilmodell | F1: Årsmodell | G1: Övrigt | H1: Ok? | I1: Till Borås | J1: Artikelnummer
A2: 1 | B2: Erich Jaeger | C2: För bilar utan REC box | D2: Kit 721999 | E2: Ford C-Max, Focus | F2: 2010>
A3: 2 | B3: Erich Jaeger | C3: 7-pol | D3: 737452 | E3: Kia Optima Kombi | F3: 2016>
A4: 3 | B4: Brink | C4: 13-Pol | D4: 744184 | E4: Land Rover Discovery 3, sport | H4: OK | I4: Ja | J4: 744184
A5: 4 | B5: Erich Jaeger | C5: 13-Pol | D5: 749178 | E5: Volvo V40 S40 | F5: 36617 | G5: Tagen till usu289
A6: 5 | B6: GM | C6: 13-Pol | E6: Opel Astra Halv och Kombi | F6: 2011?
A7: 6 | B7: Westfalia | C7: 13-Pol | D7: 307400300113 | E7: Ford S-Max, Galaxy Mondeo | F7: 2006> | G7: Tagen till gyx769
A8: 7 | B8: Erich Jaeger | C8: 13-Pol | D8: 737477 | E8: 5008, 3008 | F8: 2016> | G8: OBS- denna elsats är för icke förberedda bilar. /FP
A9: 8 | B9: Erich Jaeger | C9: 7-pol | D9: 737391 | E9: Kia Optima | F9: 2016>
A10: 9 | B10: Erich Jaeger | C10: 13-Pol | D10: 747024 | E10: Kia Optima | F10: 2016>
A11: 10 | B11: Erich Jaeger | C11: 13-Pol | D11: 748704 | E11: Kia Soul | F11: 2009>
A12: 11 | B12: Westfalia | C12: 13-Pol | D12: 36180-16 | E12: Kia Ceed HB Kombi | F12: 2012> | G12: PKJ652
A13: 12 | B13: Westfalia | C13: 7-pol | E13: Kia Ceed halvkombi , Kia Pro Ceed | F13: 2007>
A14: 13 | B14: Westfalia | C14: 13-Pol | E14: Kia Niro Hybrid | F14: 2016.09>2017.10
A15: 14 | B15: Erich Jaeger | C15: 13-Pol | D15: 747113 | E15: 3008,5008 Opel Grandland | F15: 2015>
A16: 15 | B16: Westfalia | C16: 13-Pol | D16: 303451300113 | E16: BMW X5 X6 | F16: fram till årsmodell -11/2013 | G16: Tagen till SPK169
A17: 16 | B17: Erich Jaeger | C17: 13-Pol | D17: 747266 | E17: Kia Ceed | F17: 2018>
A18: 17 | B18: Erich Jaeger | C18: 13-Pol | D18: 747266 | E18: Kia Ceed | F18: 2018> | G18: Till AMU52L
A19: 18 | B19: Erich Jaeger | C19: 13-Pol | D19: 747266 | E19: Kia Ceed | F19: 2018>
A20: 19 | B20: Erich Jaeger | C20: 7-pol | D20: 737559 | E20: Kia Ceed | F20: 2018>
A21: 20 | B21: Erich Jaeger | C21: 7-pol | D21: 737559 | E21: Kia Ceed | F21: 2018> | H21: GWZ48N
A22: 21 | B22: Erich Jaeger | C22: 7-pol | D22: 737109 | E22: Volvo S60, XC60 | H22: skickad till JHB017
A23: 22 | B23: Jaeger | C23: 7-pol | D23: 1226010100 | E23: Volvo 850, V70 mfl | F23: 93-00
A24: 23 | B24: Erich Jaeger | C24: 7-pol | D24: 737403 | E24: Volvo XC90 S90 V90 | F24: 2015>
A25: 24 | B25: Erich Jaeger | C25: 13-pol | D25: 748242 | E25: Audi,Golf,Seat mfl | H25: Ok | I25: Ja | J25: 748242
A26: 25 | B26: ECS | C26: 13-pol | D26: KI-132DX | E26: Kia flera modeller | F26: 2016>
A27: 26 | B27: ECS | C27: 13-pol | D27: KI-132DX | E27: Kia flera modeller | F27: 2016> | H27: ZEM906
A28: 27 | B28: ECS | C28: 13-pol | D28: KI-132DX | E28: Kia flera modeller | F28: 2016>
A29: 28 | B29: Erich Jaeger | C29: 13-pol | D29: 748520 | E29: Mitsubishi Outlander | F29: 2012> | G29: Ligger snart hos Tågaborg. Ev fel på denna elsatsen, ev inte. =) //TC 20/4
A30: 29 | B30: ECS | C30: 13-pol | D30: BW-028-D1 | E30: BMW, massa modeller | F30: 2013>
A31: 30 | B31: ECS | C31: 13-pol | D31: BW-028-D1 | E31: BMW, massa modeller | F31: 2013>
A32: 31 | B32: AC | C32: 13-pol | D32: 158247-37619-1 (rameder) | E32: Kia Rio 2017> | F32: 2017> | G32: Ligger hos Äpplekullen
A33: 32 | B33: Erich Jaeger | C33: 7-pol | D33: 737422 | E33: Kia Niro 2016> | F33: 2016> | G33: Retur från MTB62R | H33: OK | I33: Ja | J33: 737422
A34: 33 | B34: Erich Jaeger | C34: 13-pol | D34: 747113 | E34: Peugeot 3008 2016> Peugeot 5008 2017> Opel Grandland X 2014 Citroen C5 Aircross 2019> | G34: Endast för förberedda bilar. | H34: Ser orörd ut | I34: Ja | J34: 747113
B35: ECS | C35: 13-pol | D35: VW190H1 | E35: VW, Skoda, Audi massa modeller | F35: 2011>
B36: ECS | C36: 7-pol | D36: VW190B1 | E36: VW, Skoda, Audi massa modeller | F36: 2011>
B37: ECS | C37: 13-pol | D37: AU068H1 | E37: Audi massa modeller | F37: 2011>
B38: ECS | C38: 7-pol | D38: AU068B1 | E38: Audi massa modeller | F38: 2011>
A39: 34 | B39: Erich Jaeger | C39: 13-pol | D39: 747202 | E39: Jaguar F-pace 06/17 >> Range Rover Velar 06/17 >> | F39: 2017> | H39: OK | I39: Ja | J39: 747202
B40: Westfalia | C40: 13-pol | D40: 320134300113 | E40: Volvo V60 2010> | F40: 2010> | G40: Tror den har gott till PDK036
...

Sheet Lager Takräcke
A1: Tillverkare | B1: Namn | C1: Artikelnummer | D1: Pris rek € | E1: Pris inköp € | F1: inventering 190823 | G1: Order 190823 | H1: Totalt efter beställning | I1: Inventering 191028 | J1: Antal sålda | K1: Beställa hem | L1: Totalt efter beställning | M1: Inventering 191202 | N1: Antal sålda | O1: Beställa hem | P1: Totalt efter beställning | Q1: Inventering 191219 | R1: Antal sålda | S1: Beställa hem Pall 1 | T1: Totalt efter beställning | U1: Inventering 20-01-08 | V1: Totalt efter beställning 1 | W1: Beställ hem | X1: Totalt efter beställning | Y1: Inventering 200204 | Z1: Antal sålda | AA1: Beställ hem | AB1: Total efter beställning | AC1: Inventering 200302 | AD1: Antal sålda | AE1: Beställ hem | AF1: Totalt efter beställning | AG1: Inventering 200415 | AH1: Antal sålda | AI1: Beställa hem | AJ1: Totalt efter beställning | AK1: Inventering 200601 | AL1: Antal sålda | AM1: Beställa hem | AN1: Totalt efter beställning | AO1: Beställt 2020-07-01 | AP1: Inventering 2020-07-13 | AQ1: Beställt 2020-07-14 | AR1: Inventering 2020-08-25 | AS1: Beställt 2020-08-25 | AT1: Totalt efter beställning | AU1: Inventering 2020-09-16 | AV1: Antal sålda | AW1: Beställa hem | AX1: Totalt efter beställning | AY1: Inventering 2020-10-23 | AZ1: Inventering | BA1: Antal Sålda | BB1: Beställa hem | BC1: Totalt efter beställning | BE1: Totalt antal beställt
A2: Menabo | B2: DELTA ALU M SILVER | C2: 000095400000 | D2: 49 | E2: 20.384 | F2: 17 | G2: 0 | H2: =F2+G2 -> 17 | I2: 10 | J2: =H2-I2 -> 7 | K2: 0 | L2: =I2+K2 -> 10 | M2: 6 | N2: =L2-M2 -> 4 | O2: 6 | P2: =M2+O2 -> 12 | Q2: 5 | R2: =P2-Q2 -> 7 | S2: 12 | T2: =Q2+S2 -> 17 | U2: 0 | V2: =U2+S2 -> 12 | W2: 12 | X2: =V2+W2 -> 24 | Y2: 21 | Z2: =X2-Y2 -> 3 | AB2: =Y2+AA2 -> 21 | AC2: 19 | AD2: =AB2-AC2 -> 2 | AF2: =AC2+AE2 -> 19 | AG2: 17 | AH2: =AF2-AG2 -> 2 | AI2: 0 | AJ2: =AG2+AI2 -> 17 | AK2: 12 | AL2: =AJ2-AK2 -> 5 | AN2: =AK2+AM2 -> 12 | AO2: 12 | AR2: 11 | AS2: 6 | AT2: =AR2+AS2 -> 17 | AU2: 15 | AV2: =AT2-AU2 -> 2 | AX2: =AU2+AW2 -> 15 | AY2: 14 | AZ2: 13 | BA2: =AX2-AZ2 -> 2 | BC2: =AZ2+BB2 -> 13 | BE2: =BB2+AW2+AS2+AQ2+AO2+AM2+AJ2 -> 35
A3: Menabo | B3: DELTA ALU L SILVER | C3: 000095500000 | D3: 55.5 | E3: 23.088 | F3: 16 | G3: 0 | H3: =F3+G3 -> 16 | I3: 11 | J3: =H3-I3 -> 5 | K3: 0 | L3: =I3+K3 -> 11 | M3: 5 | N3: =L3-M3 -> 6 | O3: 12 | P3: =M3+O3 -> 17 | Q3: 14 | R3: =P3-Q3 -> 3 | T3: =Q3+S3 -> 14 | U3: 11 | V3: =U3+S3 -> 11 | W3: 8 | X3: =V3+W3 -> 19 | Y3: 12 | Z3: =X3-Y3 -> 7 | AA3: 12 | AB3: =Y3+AA3 -> 24 | AC3: 19 | AD3: =AB3-AC3 -> 5 | AF3: =AC3+AE3 -> 19 | AG3: 12 | AH3: =AF3-AG3 -> 7 | AJ3: =AG3+AI3 -> 12 | AK3: 4 | AL3: =AJ3-AK3 -> 8 | AM3: 12 | AN3: =AK3+AM3 -> 16 | AO3: 12 | AR3: 7 | AS3: 6 | AT3: =AR3+AS3 -> 13 | AU3: 11 | AV3: =AT3-AU3 -> 2 | AX3: =AU3+AW3 -> 11 | AY3: 7 | AZ3: 5 | BA3: =AX3-AZ3 -> 6 | BB3: 6 | BC3: =AZ3+BB3 -> 11 | BE3: =BB3+AW3+AS3+AQ3+AO3+AM3+AJ3 -> 48
A4: Menabo | B4: DLFIX201FP | C4: 000104900000 | D4: 36 | E4: 14.976 | F4: 3 | G4: 0 | H4: =F4+G4 -> 3 | I4: 0 | J4: =H4-I4 -> 3 | K4: 4 | L4: =I4+K4 -> 4 | M4: 3 | N4: =L4-M4 -> 1 | O4: 0 | P4: =M4+O4 -> 3 | Q4: 2 | R4: =P4-Q4 -> 1 | T4: =Q4+S4 -> 2 | U4: 0 | V4: =U4+S4 -> 0 | W4: 2 | X4: =V4+W4 -> 2 | Y4: 2 | Z4: =X4-Y4 -> 0 | AB4: =Y4+AA4 -> 2 | AC4: 2 | AD4: =AB4-AC4 -> 0 | AF4: =AC4+AE4 -> 2 | AG4: 2 | AH4: =AF4-AG4 -> 0 | AJ4: =AG4+AI4 -> 2 | AK4: 2 | AL4: =AJ4-AK4 -> 0 | AN4: =AK4+AM4 -> 2 | AO4: 1 | AR4: 1 | AS4: 1 | AT4: =AR4+AS4 -> 2 | AU4: 2 | AV4: =AT4-AU4 -> 0 | AX4: =AU4+AW4 -> 2 | AY4: 2 | AZ4: 2 | BA4: =AX4-AZ4 -> 0 | BC4: =AZ4+BB4 -> 2 | BE4: =BB4+AW4+AS4+AQ4+AO4+AM4+AJ4 -> 4
A5: Menabo | B5: DLFIX202FP | AR5: 0 | AS5: 1 | AT5: =AR5+AS5 -> 1 | AU5: 1 | AV5: =AT5-AU5 -> 0 | AX5: =AU5+AW5 -> 1 | AY5: 1 | AZ5: 1 | BA5: =AX5-AZ5 -> 0 | BC5: =AZ5+BB5 -> 1 | BE5: =BB5+AW5+AS5+AQ5+AO5+AM5+AJ5 -> 1
A6: Menabo | B6: DLFIX203FP | C6: 000105900000 | D6: 36 | E6: 14.976 | F6: 3 | G6: 0 | H6: =F6+G6 -> 3 | I6: 1 | J6: =H6-I6 -> 2 | K6: 2 | L6: =I6+K6 -> 3 | M6: 4 | N6: =L6-M6 -> -1 | O6: 0 | P6: =M6+O6 -> 4 | Q6: 4 | R6: =P6-Q6 -> 0 | T6: =Q6+S6 -> 4 | U6: 4 | V6: =U6+S6 -> 4 | X6: =V6+W6 -> 4 | Y6: 3 | Z6: =X6-Y6 -> 1 | AB6: =Y6+AA6 -> 3 | AC6: 3 | AD6: =AB6-AC6 -> 0 | AF6: =AC6+AE6 -> 3 | AG6: 2 | AH6: =AF6-AG6 -> 1 | AJ6: =AG6+AI6 -> 2 | AK6: 2 | AL6: =AJ6-AK6 -> 0 | AN6: =AK6+AM6 -> 2 | AO6: 2 | AR6: 2 | AT6: =AR6+AS6 -> 2 | AU6: 2 | AV6: =AT6-AU6 -> 0 | AX6: =AU6+AW6 -> 2 | AY6: 1 | AZ6: 2 | BA6: =AX6-AZ6 -> 0 | BC6: =AZ6+BB6 -> 2 | BE6: =BB6+AW6+AS6+AQ6+AO6+AM6+AJ6 -> 4
A7: Menabo | B7: DLFIX204FP | C7: 000106000000 | D7: 36 | E7: 14.976 | F7: 2 | G7: 0 | H7: =F7+G7 -> 2 | I7: 1 | J7: =H7-I7 -> 1 | K7: 1 | L7: =I7+K7 -> 2 | M7: 0 | N7: =L7-M7 -> 2 | O7: 3 | P7: =M7+O7 -> 3 | Q7: 2 | R7: =P7-Q7 -> 1 | T7: =Q7+S7 -> 2 | U7: 2 | V7: =U7+S7 -> 2 | X7: =V7+W7 -> 2 | Y7: 2 | Z7: =X7-Y7 -> 0 | AB7: =Y7+AA7 -> 2 | AC7: 1 | AD7: =AB7-AC7 -> 1 | AE7: 1 | AF7: =AC7+AE7 -> 2 | AG7: 2 | AH7: =AF7-AG7 -> 0 | AJ7: =AG7+AI7 -> 2 | AK7: 2 | AL7: =AJ7-AK7 -> 0 | AN7: =AK7+AM7 -> 2 | AO7: 3 | AR7: 2 | AS7: 1 | AT7: =AR7+AS7 -> 3 | AU7: 3 | AV7: =AT7-AU7 -> 0 | AX7: =AU7+AW7 -> 3 | AY7: 2 | AZ7: 2 | BA7: =AX7-AZ7 -> 1 | BC7: =AZ7+BB7 -> 2 | BE7: =BB7+AW7+AS7+AQ7+AO7+AM7+AJ7 -> 6
A8: Menabo | B8: DLFIX205FP | C8: 000106100000 | D8: 36 | E8: 14.976 | F8: 3 | G8: 0 | H8: =F8+G8 -> 3 | I8: 3 | J8: =H8-I8 -> 0 | K8: 0 | L8: =I8+K8 -> 3 | M8: 2 | N8: =L8-M8 -> 1 | O8: 1 | P8: =M8+O8 -> 3 | Q8: 3 | R8: =P8-Q8 -> 0 | T8: =Q8+S8 -> 3 | U8: 2 | V8: =U8+S8 -> 2 | X8: =V8+W8 -> 2 | Y8: 2 | Z8: =X8-Y8 -> 0 | AB8: =Y8+AA8 -> 2 | AC8: 2 | AD8: =AB8-AC8 -> 0 | AF8: =AC8+AE8 -> 2 | AG8: 2 | AH8: =AF8-AG8 -> 0 | AJ8: =AG8+AI8 -> 2 | AK8: 2 | AL8: =AJ8-AK8 -> 0 | AN8: =AK8+AM8 -> 2 | AR8: 2 | AT8: =AR8+AS8 -> 2 | AU8: 1 | AV8: =AT8-AU8 -> 1 | AX8: =AU8+AW8 -> 1 | AY8: 1 | AZ8: 1 | BA8: =AX8-AZ8 -> 0 | BC8: =AZ8+BB8 -> 1 | BE8: =BB8+AW8+AS8+AQ8+AO8+AM8+AJ8 -> 2
A9: Menabo | B9: DLFIX206FP | C9: 000106200000 | D9: 36 | E9: 14.976 | F9: 5 | G9: 0 | H9: =F9+G9 -> 5 | I9: 3 | J9: =H9-I9 -> 2 | K9: 1 | L9: =I9+K9 -> 4 | M9: 1 | N9: =L9-M9 -> 3 | O9: 2 | P9: 2 | Q9: 1 | R9: =P9-Q9 -> 1 | S9: 1 | T9: =Q9+S9 -> 2 | U9: 0 | V9: =U9+S9 -> 1 | W9: 1 | X9: =V9+W9 -> 2 | Y9: 0 | Z9: =X9-Y9 -> 2 | AA9: 2 | AB9: =Y9+AA9 -> 2 | AC9: 1 | AD9: =AB9-AC9 -> 1 | AE9: 1 | AF9: =AC9+AE9 -> 2 | AG9: 1 | AH9: =AF9-AG9 -> 1 | AI9: 1 | AJ9: =AG9+AI9 -> 2 | AK9: 1 | AL9: =AJ9-AK9 -> 1 | AM9: 1 | AN9: =AK9+AM9 -> 2 | AO9: 1 | AR9: 1 | AS9: 2 | AT9: =AR9+AS9 -> 3 | AU9: 3 | AV9: =AT9-AU9 -> 0 | AX9: =AU9+AW9 -> 3 | AY9: 3 | AZ9: 3 | BA9: =AX9-AZ9 -> 0 | BC9: =AZ9+BB9 -> 3 | BE9: =BB9+AW9+AS9+AQ9+AO9+AM9+AJ9 -> 6
A10: Menabo | B10: DLFIX208FP | C10: 000106600000 | D10: 36 | E10: 14.976 | F10: 5 | G10: 0 | H10: =F10+G10 -> 5 | I10: 3 | J10: =H10-I10 -> 2 | K10: 0 | L10: =I10+K10 -> 3 | M10: 0 | N10: =L10-M10 -> 3 | O10: 3 | P10: =M10+O10 -> 3 | Q10: 2 | R10: =P10-Q10 -> 1 | T10: =Q10+S10 -> 2 | U10: 2 | V10: =U10+S10 -> 2 | X10: =V10+W10 -> 2 | Y10: 0 | Z10: =X10-Y10 -> 2 | AA10: 2 | AB10: =Y10+AA10 -> 2 | AC10: 1 | AD10: =AB10-AC10 -> 1 | AE10: 4 | AF10: =AC10+AE10 -> 5 | AG10: 4 | AH10: =AF10-AG10 -> 1 | AJ10: =AG10+AI10 -> 4 | AK10: 1 | AL10: =AJ10-AK10 -> 3 | AM10: 2 | AN10: =AK10+AM10 -> 3 | AR10: 0 | AS10: 3 | AT10: =AR10+AS10 -> 3 | AU10: 2 | AV10: =AT10-AU10 -> 1 | AX10: =AU10+AW10 -> 2 | AY10: 1 | AZ10: 1 | BA10: =AX10-AZ10 -> 1 | BB10: 2 | BC10: =AZ10+BB10 -> 3 | BE10: =BB10+AW10+AS10+AQ10+AO10+AM10+AJ10 -> 11
A11: Menabo | B11: DLFIX209FP | C11: 000106700000 | D11: 36 | E11: 14.976 | F11: 2 | G11: 0 | H11: =F11+G11 -> 2 | I11: 2 | J11: =H11-I11 -> 0 | K11: 0 | L11: =I11+K11 -> 2 | M11: 2 | N11: =L11-M11 -> 0 | O11: 0 | P11: =M11+O11 -> 2 | Q11: 1 | R11: =P11-Q11 -> 1 | S11: 1 | T11: =Q11+S11 -> 2 | U11: 0 | V11: =U11+S11 -> 1 | W11: 1 | X11: =V11+W11 -> 2 | Y11: 2 | Z11: =X11-Y11 -> 0 | AB11: =Y11+AA11 -> 2 | AC11: 2 | AD11: =AB11-AC11 -> 0 | AF11: =AC11+AE11 -> 2 | AG11: 2 | AH11: =AF11-AG11 -> 0 | AJ11: =AG11+AI11 -> 2 | AK11: 0 | AL11: =AJ11-AK11 -> 2 | AM11: 2 | AN11: =AK11+AM11 -> 2 | AR11: 1 | AT11: =AR11+AS11 -> 1 | AU11: 0 | AV11: =AT11-AU11 -> 1 | AW11: 2 | AX11: =AU11+AW11 -> 2 | AY11: 2 | AZ11: 2 | BA11: =AX11-AZ11 -> 0 | BC11: =AZ11+BB11 -> 2 | BE11: =BB11+AW11+AS11+AQ11+AO11+AM11+AJ11 -> 6
A12: Menabo | B12: DLKIT02G | C12: 000096400000 | D12: 28 | E12: 11.648 | F12: 4 | G12: 0 | H12: =F12+G12 -> 4 | I12: 3 | J12: =H12-I12 -> 1 | K12: 0 | L12: =I12+K12 -> 3 | M12: 2 | N12: =L12-M12 -> 1 | O12: 0 | P12: =M12+O12 -> 2 | Q12: 2 | R12: =P12-Q12 -> 0 | T12: =Q12+S12 -> 2 | U12: 2 | V12: =U12+S12 -> 2 | X12: =V12+W12 -> 2 | Y12: 1 | Z12: =X12-Y12 -> 1 | AA12: 1 | AB12: =Y12+AA12 -> 2 | AC12: 3 | AD12: =AB12-AC12 -> -1 | AF12: =AC12+AE12 -> 3 | AG12: 3 | AH12: =AF12-AG12 -> 0 | AJ12: =AG12+AI12 -> 3 | AK12: 2 | AL12: =AJ12-AK12 -> 1 | AN12: =AK12+AM12 -> 2 | AR12: 0 | AS12: 1 | AT12: =AR12+AS12 -> 1 | AU12: 1 | AV12: =AT12-AU12 -> 0 | AX12: =AU12+AW12 -> 1 | AY12: 0 | AZ12: 0 | BA12: =AX12-AZ12 -> 1 | BB12: 2 | BC12: =AZ12+BB12 -> 2 | BE12: =BB12+AW12+AS12+AQ12+AO12+AM12+AJ12 -> 6
A13: Menabo | B13: DLKIT03G | C13: 000096500000 | D13: 28 | E13: 11.648 | F13: 4 | G13: 0 | H13: =F13+G13 -> 4 | I13: 2 | J13: =H13-I13 -> 2 | K13: 0 | L13: =I13+K13 -> 2 | M13: 2 | N13: =L13-M13 -> 0 | O13: 0 | P13: =M13+O13 -> 2 | Q13: 2 | R13: =P13-Q13 -> 0 | T13: =Q13+S13 -> 2 | U13: 1 | V13: =U13+S13 -> 1 | W13: 1 | X13: =V13+W13 -> 2 | Y13: 1 | Z13: =X13-Y13 -> 1 | AA13: 1 | AB13: =Y13+AA13 -> 2 | AC13: 2 | AD13: =AB13-AC13 -> 0 | AF13: =AC13+AE13 -> 2 | AG13: 1 | AH13: =AF13-AG13 -> 1 | AI13: 1 | AJ13: =AG13+AI13 -> 2 | AK13: 0 | AL13: =AJ13-AK13 -> 2 | AM13: 2 | AN13: =AK13+AM13 -> 2 | AR13: 1 | AT13: =AR13+AS13 -> 1 | AU13: 0 | AV13: =AT13-AU13 -> 1 | AW13: 2 | AX13: =AU13+AW13 -> 2 | AY13: 1 | AZ13: 1 | BA13: =AX13-AZ13 -> 1 | BB13: 1 | BC13: =AZ13+BB13 -> 2 | BE13: =BB13+AW13+AS13+AQ13+AO13+AM13+AJ13 -> 7
A14: Menabo | B14: DLKIT06G | D14: 28 | E14: 11.648 | F14: 2 | G14: 0 | H14: =F14+G14 -> 2 | I14: 2 | J14: =H14-I14 -> 0 | K14: 0 | L14: =I14+K14 -> 2 | M14: 2 | N14: =L14-M14 -> 0 | O14: 0 | P14: =M14+O14 -> 2 | Q14: 2 | R14: =P14-Q14 -> 0 | T14: =Q14+S14 -> 2 | U14: 2 | V14: =U14+S14 -> 2 | X14: =V14+W14 -> 2 | Y14: 2 | Z14: =X14-Y14 -> 0 | AB14: =Y14+AA14 -> 2 | AC14: 2 | AD14: =AB14-AC14 -> 0 | AF14: =AC14+AE14 -> 2 | AG14: 2 | AH14: =AF14-AG14 -> 0 | AJ14: =AG14+AI14 -> 2 | AK14: 2 | AL14: =AJ14-AK14 -> 0 | AN14: =AK14+AM14 -> 2 | AR14: 1 | AT14: =AR14+AS14 -> 1 | AU14: 1 | AV14: =AT14-AU14 -> 0 | AX14: =AU14+AW14 -> 1 | AY14: 1 | AZ14: 1 | BA14: =AX14-AZ14 -> 0 | BC14: =AZ14+BB14 -> 1 | BE14: =BB14+AW14+AS14+AQ14+AO14+AM14+AJ14 -> 2
A15: Menabo | B15: DLKIT07G | D15: 28 | E15: 11.648 | F15: 3 | G15: 0 | H15: =F15+G15 -> 3 | I15: 2 | J15: =H15-I15 -> 1 | K15: 0 | L15: =I15+K15 -> 2 | M15: 2 | N15: =L15-M15 -> 0 | O15: 0 | P15: =M15+O15 -> 2 | Q15: 2 | R15: =P15-Q15 -> 0 | T15: =Q15+S15 -> 2 | U15: 2 | V15: =U15+S15 -> 2 | X15: =V15+W15 -> 2 | Y15: 2 | Z15: =X15-Y15 -> 0 | AB15: =Y15+AA15 -> 2 | AC15: 2 | AD15: =AB15-AC15 -> 0 | AF15: =AC15+AE15 -> 2 | AG15: 2 | AH15: =AF15-AG15 -> 0 | AJ15: =AG15+AI15 -> 2 | AK15: 2 | AL15: =AJ15-AK15 -> 0 | AN15: =AK15+AM15 -> 2 | AR15: 2 | AT15: =AR15+AS15 -> 2 | AU15: 2 | AV15: =AT15-AU15 -> 0 | AX15: =AU15+AW15 -> 2 | AY15: 2 | AZ15: 2 | BA15: =AX15-AZ15 -> 0 | BC15: =AZ15+BB15 -> 2 | BE15: =BB15+AW15+AS15+AQ15+AO15+AM15+AJ15 -> 2
A16: Menabo | B16: DLKIT08G | C16: 000097000000 | D16: 28 | E16: 11.648 | F16: 3 | G16: 0 | H16: =F16+G16 -> 3 | I16: 2 | J16: =H16-I16 -> 1 | K16: 0 | L16: =I16+K16 -> 2 | M16: 2 | N16: =L16-M16 -> 0 | O16: 0 | P16: =M16+O16 -> 2 | Q16: 1 | R16: =P16-Q16 -> 1 | S16: 1 | T16: =Q16+S16 -> 2 | U16: 1 | V16: =U16+S16 -> 2 | X16: =V16+W16 -> 2 | Y16: 2 | Z16: =X16-Y16 -> 0 | AB16: =Y16+AA16 -> 2 | AC16: 2 | AD16: =AB16-AC16 -> 0 | AF16: =AC16+AE16 -> 2 | AG16: 1 | AH16: =AF16-AG16 -> 1 | AI16: 1 | AJ16: =AG16+AI16 -> 2 | AK16: 2 | AL16: =AJ16-AK16 -> 0 | AN16: =AK16+AM16 -> 2 | AR16: 0 | AS16: 1 | AT16: =AR16+AS16 -> 1 | AU16: 1 | AV16: =AT16-AU16 -> 0 | AX16: =AU16+AW16 -> 1 | AY16: 1 | AZ16: 1 | BA16: =AX16-AZ16 -> 0 | BC16: =AZ16+BB16 -> 1 | BE16: =BB16+AW16+AS16+AQ16+AO16+AM16+AJ16 -> 3
A17: Menabo | B17: DLKIT10G | C17: 000097200000 | D17: 28 | E17: 11.648 | F17: 2 | G17: 0 | H17: 1 | I17: 1 | J17: =H17-I17 -> 0 | K17: 0 | L17: =I17+K17 -> 1 | M17: 1 | N17: =L17-M17 -> 0 | O17: 0 | P17: =M17+O17 -> 1 | Q17: 1 | R17: =P17-Q17 -> 0 | T17: =Q17+S17 -> 1 | U17: 1 | V17: =U17+S17 -> 1 | W17: 1 | X17: =V17+W17 -> 2 | Y17: 1 | Z17: =X17-Y17 -> 1 | AA17: 1 | AB17: =Y17+AA17 -> 2 | AC17: 2 | AD17: =AB17-AC17 -> 0 | AF17: =AC17+AE17 -> 2 | AG17: 2 | AH17: =AF17-AG17 -> 0 | AJ17: =AG17+AI17 -> 2 | AK17: 1 | AL17: =AJ17-AK17 -> 1 | AM17: 1 | AN17: =AK17+AM17 -> 2 | AO17: 2 | AR17: 0 | AS17: 2 | AT17: =AR17+AS17 -> 2 | AU17: 2 | AV17: =AT17-AU17 -> 0 | AX17: =AU17+AW17 -> 2 | AY17: 2 | AZ17: 2 | BA17: =AX17-AZ17 -> 0 | BC17: =AZ17+BB17 -> 2 | BE17: =BB17+AW17+AS17+AQ17+AO17+AM17+AJ17 -> 7
A18: Menabo | B18: DLKIT13G | D18: 28 | E18: 11.648 | U18: 1 | V18: =U18+S18 -> 1 | W18: 1 | X18: =V18+W18 -> 2 | Y18: 2 | Z18: =X18-Y18 -> 0 | AB18: =Y18+AA18 -> 2 | AC18: 2 | AD18: =AB18-AC18 -> 0 | AF18: =AC18+AE18 -> 2 | AG18: 2 | AH18: =AF18-AG18 -> 0 | AJ18: =AG18+AI18 -> 2 | AK18: 2 | AL18: =AJ18-AK18 -> 0 | AN18: =AK18+AM18 -> 2 | AR18: 1 | AT18: =AR18+AS18 -> 1 | AU18: 1 | AV18: =AT18-AU18 -> 0 | AX18: =AU18+AW18 -> 1 | AY18: 1 | AZ18: 1 | BA18: =AX18-AZ18 -> 0 | BC18: =AZ18+BB18 -> 1 | BE18: =BB18+AW18+AS18+AQ18+AO18+AM18+AJ18 -> 2
A19: Menabo | B19: DLKIT17G | C19: 000097900000 | D19: 28 | E19: 11.648 | F19: 6 | G19: 0 | H19: =F19+G19 -> 6 | I19: 6 | J19: =H19-I19 -> 0 | K19: 0 | L19: =I19+K19 -> 6 | M19: 6 | N19: =L19-M19 -> 0 | O19: 0 | P19: =M19+O19 -> 6 | Q19: 5 | R19: =P19-Q19 -> 1 | T19: =Q19+S19 -> 5 | U19: 5 | V19: =U19+S19 -> 5 | X19: =V19+W19 -> 5 | Y19: 5 | Z19: =X19-Y19 -> 0 | AB19: =Y19+AA19 -> 5 | AC19: 4 | AD19: =AB19-AC19 -> 1 | AF19: =AC19+AE19 -> 4 | AG19: 4 | AH19: =AF19-AG19 -> 0 | AJ19: =AG19+AI19 -> 4 | AK19: 3 | AL19: =AJ19-AK19 -> 1 | AN19: =AK19+AM19 -> 3 | AR19: 2 | AT19: =AR19+AS19 -> 2 | AU19: 2 | AV19: =AT19-AU19 -> 0 | AX19: =AU19+AW19 -> 2 | AY19: 1 | AZ19: 0 | BA19: =AX19-AZ19 -> 2 | BB19: 2 | BC19: =AZ19+BB19 -> 2 | BE19: =BB19+AW19+AS19+AQ19+AO19+AM19+AJ19 -> 6
A20: Menabo | B20: DLKIT19G | C20: 000098100000 | D20: 28 | E20: 11.648 | F20: 0 | G20: 2 | H20: =F20+G20 -> 2 | I20: 0 | J20: =H20-I20 -> 2 | K20: 2 | L20: =I20+K20 -> 2 | M20: 1 | N20: =L20-M20 -> 1 | O20: 1 | P20: =M20+O20 -> 2 | Q20: 1 | R20: =P20-Q20 -> 1 | S20: 1 | T20: =Q20+S20 -> 2 | U20: 1 | V20: =U20+S20 -> 2 | X20: =V20+W20 -> 2 | Y20: 1 | Z20: =X20-Y20 -> 1 | AA20: 1 | AB20: =Y20+AA20 -> 2 | AC20: 2 | AD20: =AB20-AC20 -> 0 | AF20: =AC20+AE20 -> 2 | AG20: 1 | AH20: =AF20-AG20 -> 1 | AI20: 1 | AJ20: =AG20+AI20 -> 2 | AK20: 1 | AL20: =AJ20-AK20 -> 1 | AM20: 1 | AN20: =AK20+AM20 -> 2 | AR20: 0 | AS20: 1 | AT20: =AR20+AS20 -> 1 | AU20: 1 | AV20: =AT20-AU20 -> 0 | AX20: =AU20+AW20 -> 1 | AY20: 0 | AZ20: 0 | BA20: =AX20-AZ20 -> 1 | BB20: 2 | BC20: =AZ20+BB20 -> 2 | BE20: =BB20+AW20+AS20+AQ20+AO20+AM20+AJ20 -> 6
A21: Menabo | B21: DLKIT27G | C21: 000098900000 | D21: 28 | E21: 11.648 | F21: 4 | G21: 0 | H21: =F21+G21 -> 4 | I21: 4 | J21: =H21-I21 -> 0 | K21: 0 | L21: =I21+K21 -> 4 | M21: 4 | N21: =L21-M21 -> 0 | O21: 0 | P21: =M21+O21 -> 4 | Q21: 4 | R21: =P21-Q21 -> 0 | T21: =Q21+S21 -> 4 | U21: 4 | V21: =U21+S21 -> 4 | X21: =V21+W21 -> 4 | Y21: 2 | Z21: =X21-Y21 -> 2 | AB21: =Y21+AA21 -> 2 | AC21: 1 | AD21: =AB21-AC21 -> 1 | AE21: 1 | AF21: =AC21+AE21 -> 2 | AG21: 2 | AH21: =AF21-AG21 -> 0 | AJ21: =AG21+AI21 -> 2 | AK21: 2 | AL21: =AJ21-AK21 -> 0 | AN21: =AK21+AM21 -> 2 | AR21: 1 | AT21: =AR21+AS21 -> 1 | AU21: 1 | AV21: =AT21-AU21 -> 0 | AX21: =AU21+AW21 -> 1 | AY21: 1 | AZ21: 1 | BA21: =AX21-AZ21 -> 0 | BC21: =AZ21+BB21 -> 1 | BE21: =BB21+AW21+AS21+AQ21+AO21+AM21+AJ21 -> 2
